"use strict"

describe "Assert interface:", =>
    promise = null
    error = new Error("boo")
    custom = "No. I am your father."

    describe "when the promise is fulfilled", =>
        beforeEach =>
            promise = fulfilledPromise(foo: "bar")
            return undefined

        describe ".isFulfilled(promise)", =>
            shouldPass => assert.isFulfilled(promise)

        describe ".becomes(promise, correctValue)", =>
            shouldPass => assert.becomes(promise, foo: "bar")
        describe ".becomes(promise, incorrectValue)", =>
            shouldFail
                op: => assert.becomes(promise, baz: "quux")
                message: "to deeply equal { baz: 'quux' }"

        describe ".becomes(promise, incorrectValue, custom)", =>
            shouldFail
                op: => assert.becomes(promise, baz: "quux", custom)
                message: custom

        describe ".doesNotBecome(promise, correctValue)", =>
            shouldFail
                op: => assert.doesNotBecome(promise, foo: "bar")
                message: "to not deeply equal { foo: 'bar' }"
        describe ".doesNotBecome(promise, incorrectValue)", =>
            shouldPass => assert.doesNotBecome(promise, baz: "quux")

        describe ".doesNotBecome(promise, correctValue, custom)", =>
            shouldFail
                op: => assert.doesNotBecome(promise, foo: "bar", custom)
                message: custom

        describe ".isRejected(promise)", =>
            shouldFail
                op: => assert.isRejected(promise)
                message: "to be rejected"
        describe ".isRejected(promise, TypeError)", =>
            shouldFail
                op: => assert.isRejected(promise, TypeError)
                message: "to be rejected"
        describe ".isRejected(promise, /regexp/)", =>
            shouldFail
                op: => assert.isRejected(promise, /regexp/)
                message: "to be rejected"
        describe ".isRejected(promise, TypeError, /regexp/)", =>
            shouldFail
                op: => assert.isRejected(promise, TypeError, /regexp/)
                message: "to be rejected"
        describe ".isRejected(promise, errorInstance)", =>
            shouldFail
                op: => assert.isRejected(promise, error)
                message: "to be rejected"
        # Chai never interprets the 3rd parameter to assert.throws as
        # a custom error message. This is what we are checking here.
        describe ".isRejected(promise, /quux/, custom)", =>
            shouldFail
                op: => assert.isRejected(promise, /quux/, custom)
                notMessage: custom


    describe "when the promise is rejected", =>
        beforeEach =>
            promise = rejectedPromise(error)
            return undefined

        describe ".isFulfilled(promise)", =>
            shouldFail
                op: => assert.isFulfilled(promise)
                message: "to be fulfilled"

        describe ".isFulfilled(promise, custom)", =>
            shouldFail
                op: => assert.isFulfilled(promise, custom)
                message: custom

        describe ".isRejected(promise)", =>
            shouldPass => assert.isRejected(promise)

        describe ".isRejected(promise, theError)", =>
            shouldPass => assert.isRejected(promise, error)

        describe ".isRejected(promise, differentError)", =>
            shouldFail
                op: => assert.isRejected(promise, new Error)
                message: "to be rejected with"

        # Chai never interprets the 3rd parameter to assert.throws as
        # a custom error message. This is what we are checking here.
        describe ".isRejected(promise, differentError, custom)", =>
            shouldFail
                op: => assert.isRejected(promise, new Error, custom)
                notMessage: custom

        describe "with an Error having message 'foo bar'", =>
            beforeEach =>
                promise = rejectedPromise(new Error("foo bar"))
                return undefined

            describe ".isRejected(promise, 'bar')", =>
                shouldPass => assert.isRejected(promise, "bar")

            describe ".isRejected(promise, 'bar', custom)", =>
                shouldPass => assert.isRejected(promise, "bar", custom)

            describe ".isRejected(promise, /bar/)", =>
                shouldPass => assert.isRejected(promise, /bar/)

            describe ".isRejected(promise, /bar/, custom)", =>
                shouldPass => assert.isRejected(promise, /bar/, custom)

            describe ".isRejected(promise, 'quux')", =>
                shouldFail
                    op: => assert.isRejected(promise, "quux")
                    message: "to be rejected with"

            # Chai 3.5.0 never interprets the 3rd parameter to assert.throws as
            # a custom error message. This is what we are checking here.
            describe ".isRejected(promise, 'quux', custom)", =>
                shouldFail
                    op: => assert.isRejected(promise, "quux", custom)
                    notMessage: custom

            describe ".isRejected(promise, /quux/)", =>
                shouldFail
                    op: => assert.isRejected(promise, /quux/)
                    message: "to be rejected with"

        describe "with a RangeError", =>
            beforeEach =>
                promise = rejectedPromise(new RangeError)
                return undefined

            describe ".isRejected(promise, RangeError)", =>
                shouldPass => assert.isRejected(promise, RangeError)

            describe ".isRejected(promise, TypeError)", =>
                shouldFail
                    op: => assert.isRejected(promise, TypeError)
                    message: "to be rejected"

        describe "with a RangeError having a message 'foo bar'", =>
            beforeEach =>
                promise = rejectedPromise(new RangeError("foo bar"))
                return undefined

            describe ".isRejected(promise, RangeError, 'foo')", =>
                shouldPass => assert.isRejected(promise, RangeError, "foo")

            describe ".isRejected(promise, RangeError, /bar/)", =>
                shouldPass => assert.isRejected(promise, RangeError, /bar/)

            describe ".isRejected(promise, RangeError, 'quux')", =>
                shouldFail
                    op: => assert.isRejected(promise, RangeError, "quux")
                    message: "to be rejected with an error including 'quux' but got 'foo bar'"

            describe ".isRejected(promise, RangeError, /quux/)", =>
                shouldFail
                    op: => assert.isRejected(promise, RangeError, /quux/)
                    message: "to be rejected with an error matching /quux/ but got 'foo bar'"

            describe ".isRejected(promise, TypeError, 'foo')", =>
                shouldFail
                    op: => assert.isRejected(promise, TypeError, 'foo')
                    message: "to be rejected with 'TypeError' but it was rejected with 'RangeError: foo bar'"
            describe ".isRejected(promise, TypeError, /bar/)", =>
                shouldFail
                    op: => assert.isRejected(promise, TypeError, /bar/)
                    message: "to be rejected with 'TypeError' but it was rejected with 'RangeError: foo bar'"

            describe ".isRejected(promise, TypeError, 'quux')", =>
                shouldFail
                    op: => assert.isRejected(promise, TypeError, 'quux')
                    message: "to be rejected with 'TypeError' but it was rejected with 'RangeError: foo bar'"
            describe ".isRejected(promise, TypeError, /quux/)", =>
                shouldFail
                    op: => assert.isRejected(promise, TypeError, /quux/)
                    message: "to be rejected with 'TypeError' but it was rejected with 'RangeError: foo bar'"

            describe ".isRejected(promise, RangeError, 'foo', custom)", =>
                shouldPass => assert.isRejected(promise, RangeError, "foo", custom)

            describe ".isRejected(promise, RangeError, /bar/, custom)", =>
                shouldPass => assert.isRejected(promise, RangeError, /bar/, custom)

            describe ".isRejected(promise, RangeError, 'quux', custom)", =>
                shouldFail
                    op: => assert.isRejected(promise, RangeError, "quux", custom)
                    message: custom

            describe ".isRejected(promise, RangeError, /quux/, custom)", =>
                shouldFail
                    op: => assert.isRejected(promise, RangeError, /quux/, custom)
                    message: custom

            describe ".isRejected(promise, RangeError, undefined, custom)", =>
                shouldPass => assert.isRejected(promise, RangeError, undefined, custom)

            describe ".isRejected(promise, TypeError, undefined, custom)", =>
                shouldFail
                op: => assert.isRejected(promise, TypeError, undefined, custom)
                message: custom
