"use strict"

describe "Promise-specific extensions:", =>
    promise = null
    error = new Error("boo")

    assertingDoneFactory = (done) =>
        (result) =>
            try
                expect(result).to.equal(error)
            catch assertionError
                return done(assertionError)

            done()

    describe "when the promise is fulfilled", =>
        beforeEach =>
            promise = fulfilledPromise()

        describe ".fulfilled", =>
            shouldPass => promise.should.be.fulfilled
        describe ".not.fulfilled", =>
            shouldFail
                op: => promise.should.not.be.fulfilled
                message: "not to be fulfilled but it was fulfilled with undefined"

        describe ".rejected", =>
            shouldFail
              op: => promise.should.be.rejected
              message: "to be rejected but it was fulfilled with undefined"
        describe ".rejectedWith(TypeError)", =>
            shouldFail
                op: => promise.should.be.rejectedWith(TypeError)
                message: "to be rejected with 'TypeError' but it was fulfilled with undefined"
        describe ".rejectedWith('message substring')", =>
            shouldFail
                op: => promise.should.be.rejectedWith("message substring")
                message: "to be rejected with an error including 'message substring' but it was fulfilled with " +
                         "undefined"
        describe ".rejectedWith(/regexp/)", =>
            shouldFail
                op: => promise.should.be.rejectedWith(/regexp/)
                message: "to be rejected with an error matching /regexp/ but it was fulfilled with undefined"
        describe ".rejectedWith(TypeError, 'message substring')", =>
            shouldFail
                op: => promise.should.be.rejectedWith(TypeError, "message substring")
                message: "to be rejected with 'TypeError' but it was fulfilled with undefined"
        describe ".rejectedWith(TypeError, /regexp/)", =>
            shouldFail
                op: => promise.should.be.rejectedWith(TypeError, /regexp/)
                message: "to be rejected with 'TypeError' but it was fulfilled with undefined"
        describe ".rejectedWith(errorInstance)", =>
            shouldFail
                op: => promise.should.be.rejectedWith(error)
                message: "to be rejected with [Error: boo] but it was fulfilled with undefined"

        describe ".not.rejected", =>
            shouldPass => promise.should.not.be.rejected
        describe ".not.rejectedWith(TypeError)", =>
            shouldPass => promise.should.not.be.rejectedWith(TypeError)
        describe ".not.rejectedWith('message substring')", =>
            shouldPass => promise.should.not.be.rejectedWith("message substring")
        describe ".not.rejectedWith(/regexp/)", =>
            shouldPass => promise.should.not.be.rejectedWith(/regexp/)
        describe ".not.rejectedWith(TypeError, 'message substring')", =>
            shouldPass => promise.should.not.be.rejectedWith(TypeError, "message substring")
        describe ".not.rejectedWith(TypeError, /regexp/)", =>
            shouldPass => promise.should.not.be.rejectedWith(TypeError, /regexp/)
        describe ".not.rejectedWith(errorInstance)", =>
            shouldPass => promise.should.not.be.rejectedWith(error)

        describe ".should.notify(done)", =>
            it "should pass the test", (done) =>
                promise.should.notify(done)

    describe "when the promise is rejected", =>
        beforeEach =>
            promise = rejectedPromise(error)

        describe ".fulfilled", =>
            shouldFail
                op: => promise.should.be.fulfilled
                message: "to be fulfilled but it was rejected with [Error: boo]"
        describe ".not.fulfilled", =>
            shouldPass => promise.should.not.be.fulfilled

        describe ".rejected", =>
            shouldPass => promise.should.be.rejected

        describe ".rejectedWith(theError)", =>
            shouldPass => promise.should.be.rejectedWith(error)
        describe ".not.rejectedWith(theError)", =>
            shouldFail
                op: => promise.should.not.be.rejectedWith(error)
                message: "not to be rejected with [Error: boo]"

        describe ".rejectedWith(differentError)", =>
            shouldFail
                op: => promise.should.be.rejectedWith(new Error)
                message: "to be rejected with [Error] but it was rejected with [Error: boo]"
        describe ".not.rejectedWith(differentError)", =>
            shouldPass => promise.should.not.be.rejectedWith(new Error)

        describe "with an Error having message 'foo bar'", =>
            beforeEach =>
                promise = rejectedPromise(new Error("foo bar"))

            describe ".rejectedWith('foo')", =>
                shouldPass => promise.should.be.rejectedWith("foo")
            describe ".rejectedWith(/bar/)", =>
                shouldPass => promise.should.be.rejectedWith(/bar/)

            describe ".rejectedWith('quux')", =>
                shouldFail
                    op: => promise.should.be.rejectedWith("quux")
                    message: "to be rejected with an error including 'quux' but got 'foo bar'"
            describe ".rejectedWith(/quux/)", =>
                shouldFail
                    op: => promise.should.be.rejectedWith(/quux/)
                    message: "to be rejected with an error matching /quux/ but got 'foo bar'"

            describe ".not.rejectedWith('foo')", =>
                shouldFail
                    op: => promise.should.not.be.rejectedWith("foo")
                    message: "not to be rejected with an error including 'foo'"
            describe ".not.rejectedWith(/bar/)", =>
                shouldFail
                    op: => promise.should.not.be.rejectedWith(/bar/)
                    message: "not to be rejected with an error matching /bar/"

            describe ".not.rejectedWith('quux')", =>
                shouldPass => promise.should.not.be.rejectedWith("quux")
            describe ".not.rejectedWith(/quux/)", =>
                shouldPass => promise.should.not.be.rejectedWith(/quux/)

        describe "with a RangeError", =>
            beforeEach =>
                promise = rejectedPromise(new RangeError)

            describe ".rejectedWith(RangeError)", =>
                shouldPass => promise.should.be.rejectedWith(RangeError)
            describe ".rejectedWith(TypeError)", =>
                shouldFail
                    op: => promise.should.be.rejectedWith(TypeError)
                    message: "to be rejected with 'TypeError' but it was rejected with [RangeError]"

            describe ".not.rejectedWith(RangeError)", =>
                shouldFail
                    op: => promise.should.not.be.rejectedWith(RangeError)
                    message: "not to be rejected with 'RangeError' but it was rejected with [RangeError]"
            describe ".not.rejectedWith(TypeError)", =>
                shouldPass => promise.should.not.be.rejectedWith(TypeError)

        describe "with a RangeError having a message 'foo bar'", =>
            beforeEach =>
                promise = rejectedPromise(new RangeError("foo bar"))

            describe ".rejectedWith(RangeError, 'foo')", =>
                shouldPass => promise.should.be.rejectedWith(RangeError, "foo")
            describe ".rejectedWith(RangeError, /bar/)", =>
                shouldPass => promise.should.be.rejectedWith(RangeError, /bar/)

            describe ".rejectedWith(RangeError, 'quux')", =>
                shouldFail
                    op: => promise.should.be.rejectedWith(RangeError, "quux")
                    message: "to be rejected with an error including 'quux' but got 'foo bar'"
            describe ".rejectedWith(RangeError, /quux/)", =>
                shouldFail
                    op: => promise.should.be.rejectedWith(RangeError, /quux/)
                    message: "to be rejected with an error matching /quux/ but got 'foo bar'"

            describe ".rejectedWith(TypeError, 'foo')", =>
                shouldFail
                    op: => promise.should.be.rejectedWith(TypeError)
                    message: "to be rejected with 'TypeError' but it was rejected with [RangeError: foo bar]"
            describe ".rejectedWith(TypeError, /bar/)", =>
                shouldFail
                    op: => promise.should.be.rejectedWith(TypeError)
                    message: "to be rejected with 'TypeError' but it was rejected with [RangeError: foo bar]"

            describe ".rejectedWith(TypeError, 'quux')", =>
                shouldFail
                    op: => promise.should.be.rejectedWith(TypeError)
                    message: "to be rejected with 'TypeError' but it was rejected with [RangeError: foo bar]"
            describe ".rejectedWith(TypeError, /quux/)", =>
                shouldFail
                    op: => promise.should.be.rejectedWith(TypeError)
                    message: "to be rejected with 'TypeError' but it was rejected with [RangeError: foo bar]"

            describe ".not.rejectedWith(RangeError, 'foo')", =>
                shouldFail
                    op: => promise.should.not.be.rejectedWith(RangeError)
                    message: "not to be rejected with 'RangeError' but it was rejected with [RangeError: foo bar]"
            describe ".not.rejectedWith(RangeError, /bar/)", =>
                shouldFail
                    op: => promise.should.not.be.rejectedWith(RangeError)
                    message: "not to be rejected with 'RangeError' but it was rejected with [RangeError: foo bar]"

            describe ".not.rejectedWith(RangeError, 'quux')", =>
                shouldFail
                    op: => promise.should.not.be.rejectedWith(RangeError)
                    message: "not to be rejected with 'RangeError' but it was rejected with [RangeError: foo bar]"
            describe ".not.rejectedWith(RangeError, /quux/)", =>
                shouldFail
                    op: => promise.should.not.be.rejectedWith(RangeError)
                    message: "not to be rejected with 'RangeError' but it was rejected with [RangeError: foo bar]"

            describe ".not.rejectedWith(TypeError, 'foo')", =>
                shouldFail
                    op: => promise.should.not.be.rejectedWith(TypeError, "foo")
                    message: "not to be rejected with an error including 'foo'"
            describe ".not.rejectedWith(TypeError, /bar/)", =>
                shouldFail
                    op: => promise.should.not.be.rejectedWith(TypeError, /bar/)
                    message: "not to be rejected with an error matching /bar/"

            describe ".not.rejectedWith(TypeError, 'quux')", =>
                shouldPass => promise.should.not.be.rejectedWith(TypeError, "quux")
            describe ".not.rejectedWith(TypeError, /quux/)", =>
                shouldPass => promise.should.not.be.rejectedWith(TypeError, /quux/)

        describe ".should.notify(done)", =>
            it "should fail the test with the original error", (done) =>
                promise.should.notify(assertingDoneFactory(done))

    describe ".should.notify with chaining (GH-3)", =>
        describe "the original promise is fulfilled", =>
            beforeEach => promise = fulfilledPromise()

            describe "and the follow-up promise is fulfilled", =>
                beforeEach => promise = promise.then(=>)

                it "should pass the test", (done) =>
                    promise.should.notify(done)

            describe "but the follow-up promise is rejected", =>
                beforeEach => promise = promise.then(=> throw error)

                it "should fail the test with the error from the follow-up promise", (done) =>
                    promise.should.notify(assertingDoneFactory(done))

        describe "the original promise is rejected", =>
            beforeEach => promise = rejectedPromise(error)

            describe "but the follow-up promise is fulfilled", =>
                beforeEach => promise = promise.then(=>)

                it "should fail the test with the error from the original promise", (done) =>
                    promise.should.notify(assertingDoneFactory(done))

            describe "and the follow-up promise is rejected", =>
                beforeEach => promise = promise.then(=> throw new Error("follow up"))

                it "should fail the test with the error from the original promise", (done) =>
                    promise.should.notify(assertingDoneFactory(done))

    describe "Using with non-thenables", =>
        describe "A number", =>
            number = 5

            it "should fail for .fulfilled", =>
                expect(=> number.should.be.fulfilled).to.throw(TypeError, "not a thenable")
            it "should fail for .rejected", =>
                expect(=> number.should.be.rejected).to.throw(TypeError, "not a thenable")
            it "should fail for .become", =>
                expect(=> number.should.become(5)).to.throw(TypeError, "not a thenable")
            it "should fail for .eventually", =>
                expect(=> number.should.eventually.equal(5)).to.throw(TypeError, "not a thenable")
            it "should fail for .notify", =>
                expect(=> number.should.notify(=>)).to.throw(TypeError, "not a thenable")

    describe "Using together with other Chai as Promised asserters", =>
        describe ".fulfilled.and.eventually.equal(42)", =>
            shouldPass => fulfilledPromise(42).should.be.fulfilled.and.eventually.equal(42)
        describe ".fulfilled.and.rejected", =>
            shouldFail
                op: => fulfilledPromise(42).should.be.fulfilled.and.rejected
                message: "to be rejected but it was fulfilled with 42"

        describe ".rejected.and.eventually.equal(42)", =>
            shouldPass => rejectedPromise(42).should.be.rejected.and.eventually.equal(42)
        describe ".rejected.and.become(42)", =>
            shouldPass => rejectedPromise(42).should.be.rejected.and.become(42)

    describe "With promises that only become rejected later (GH-24)", =>
        it "should wait for them", (done) =>
            deferred = defer()
            deferred.promise.should.be.rejectedWith("error message").and.notify(done)

            setTimeout(
                => deferred.reject(new Error("error message"))
                100
            )

    describe "`rejectedWith` with non-`Error` rejection reasons (GH-33)", =>
        shouldPass => rejectedPromise(42).should.be.rejectedWith(42)

    if process.env.PROMISIFY_WITH in ["Q", "CUSTOM"]
      describe "Using Q promise with PROMISIFY_WITH=" + process.env.PROMISIFY_WITH, =>
        it "fin and done methods should work", (done) =>
          Q = require "q"
          promise = Q("1234");
          promise.should.become("1234").fin( ->
            done();
          ).done();

